Workbook

Sheet Read Me
B2: SEMS - User Acceptance Testing workbook
B3: Secure Event Management System, Universiti Poly-Tech Malaysia
B5: How to use this workbook
B6: 1. | C6: Test Cases holds the 48 test scenarios. Do not type in it: its Executed / Pass / Fail / Blocked / Pass rate columns are calculated from Results.
B7: 2. | C7: Results: add one row per tester per test case (Tester ID, Role, TC ID, Result). Paste rows from the Google Form export here.
B8: 3. | C8: Defect Log: add one row for every problem found. Link it to a TC ID. Keep the Status up to date.
B9: 4. | C9: Survey: paste the Google Form response rows into columns A to S (same order as the form). The SUS score is calculated for you (0 to 100).
B10: 5. | C10: Summary: shows pass rates, defects, SUS and whether each acceptance criterion is met. Nothing to type there.
B11: 6. | C11: Type only in Results, Defect Log, Survey and the yellow numbers on Testers. Everything else is calculated, so leave it alone. The three data sheets start empty.
B13: Result codes
B14: Pass | C14: The system did what the Expected result says.
B15: Fail | C15: The system did something different or broke. Log a defect.
B16: Blocked | C16: You could not run the case (missing data, earlier step failed). Say why in the comment.
B18: Defect severity
B19: Critical | C19: Cannot continue, data is lost or exposed, or another role's data is visible. Must be fixed before acceptance.
B20: Major | C20: A main task fails or gives wrong results, but there is a workaround.
B21: Minor | C21: A small problem that does not stop the task (unclear message, awkward layout).
B22: Cosmetic | C22: Spelling, alignment or colour issues only.
B24: Example rows (format only - do not copy into the data sheets)
B25: Sheet | C25: Example row
B26: Results | C26: Tester ID: T07 | Name: Aina | Role: Club Committee | TC ID: CLB-04 | Result: Fail | Comment: Total shows RM 0.00 after deleting a row | Date: 2026-11-02 | Defect: D-004
B27: Defect Log | C27: D-004 | 2026-11-02 | T07 | CLB-04 | Club Committee | Budget total wrong after removing a row | Steps: add 3 rows, remove the 2nd | Major | Open
B28: Survey | C28: 2026-11-02 10:41 | T07 | Phone | SUS answers 4,2,4,1,4,2,5,1,4,2 (gives SUS 82.5) | UAT answers 4,4,5 | open answers | Recommend: Yes

Sheet Summary
B2: UAT summary
B3: All figures are calculated from the Results, Defect Log and Survey sheets.
B5: 1. Test execution by role
B6: Role | C6: Test cases | D6: Executions | E6: Pass | F6: Fail | G6: Blocked | H6: Pass rate
B7: General | C7: =COUNTIF('Test Cases'!$B$2:$B$49,B7) | D7: =SUMIFS('Test Cases'!$J$2:$J$49,'Test Cases'!$B$2:$B$49,$B7) | E7: =SUMIFS('Test Cases'!$K$2:$K$49,'Test Cases'!$B$2:$B$49,$B7) | F7: =SUMIFS('Test Cases'!$L$2:$L$49,'Test Cases'!$B$2:$B$49,$B7) | G7: =SUMIFS('Test Cases'!$M$2:$M$49,'Test Cases'!$B$2:$B$49,$B7) | H7: =IF(D7=0,"-",E7/D7)
B8: Club Committee | C8: =COUNTIF('Test Cases'!$B$2:$B$49,B8) | D8: =SUMIFS('Test Cases'!$J$2:$J$49,'Test Cases'!$B$2:$B$49,$B8) | E8: =SUMIFS('Test Cases'!$K$2:$K$49,'Test Cases'!$B$2:$B$49,$B8) | F8: =SUMIFS('Test Cases'!$L$2:$L$49,'Test Cases'!$B$2:$B$49,$B8) | G8: =SUMIFS('Test Cases'!$M$2:$M$49,'Test Cases'!$B$2:$B$49,$B8) | H8: =IF(D8=0,"-",E8/D8)
B9: HEPA Officer | C9: =COUNTIF('Test Cases'!$B$2:$B$49,B9) | D9: =SUMIFS('Test Cases'!$J$2:$J$49,'Test Cases'!$B$2:$B$49,$B9) | E9: =SUMIFS('Test Cases'!$K$2:$K$49,'Test Cases'!$B$2:$B$49,$B9) | F9: =SUMIFS('Test Cases'!$L$2:$L$49,'Test Cases'!$B$2:$B$49,$B9) | G9: =SUMIFS('Test Cases'!$M$2:$M$49,'Test Cases'!$B$2:$B$49,$B9) | H9: =IF(D9=0,"-",E9/D9)
B10: Admin | C10: =COUNTIF('Test Cases'!$B$2:$B$49,B10) | D10: =SUMIFS('Test Cases'!$J$2:$J$49,'Test Cases'!$B$2:$B$49,$B10) | E10: =SUMIFS('Test Cases'!$K$2:$K$49,'Test Cases'!$B$2:$B$49,$B10) | F10: =SUMIFS('Test Cases'!$L$2:$L$49,'Test Cases'!$B$2:$B$49,$B10) | G10: =SUMIFS('Test Cases'!$M$2:$M$49,'Test Cases'!$B$2:$B$49,$B10) | H10: =IF(D10=0,"-",E10/D10)
B11: All roles | C11: =SUM(C7:C10) | D11: =SUM(D7:D10) | E11: =SUM(E7:E10) | F11: =SUM(F7:F10) | G11: =SUM(G7:G10) | H11: =IF(D11=0,"-",E11/D11)
B13: 2. Test execution by priority
B14: Priority | C14: Test cases | D14: Executions | E14: Pass | F14: Fail | G14: Blocked | H14: Pass rate
B15: High | C15: =COUNTIF('Test Cases'!$E$2:$E$49,B15) | D15: =SUMIFS('Test Cases'!$J$2:$J$49,'Test Cases'!$E$2:$E$49,$B15) | E15: =SUMIFS('Test Cases'!$K$2:$K$49,'Test Cases'!$E$2:$E$49,$B15) | F15: =SUMIFS('Test Cases'!$L$2:$L$49,'Test Cases'!$E$2:$E$49,$B15) | G15: =SUMIFS('Test Cases'!$M$2:$M$49,'Test Cases'!$E$2:$E$49,$B15) | H15: =IF(D15=0,"-",E15/D15)
B16: Medium | C16: =COUNTIF('Test Cases'!$E$2:$E$49,B16) | D16: =SUMIFS('Test Cases'!$J$2:$J$49,'Test Cases'!$E$2:$E$49,$B16) | E16: =SUMIFS('Test Cases'!$K$2:$K$49,'Test Cases'!$E$2:$E$49,$B16) | F16: =SUMIFS('Test Cases'!$L$2:$L$49,'Test Cases'!$E$2:$E$49,$B16) | G16: =SUMIFS('Test Cases'!$M$2:$M$49,'Test Cases'!$E$2:$E$49,$B16) | H16: =IF(D16=0,"-",E16/D16)
B17: Low | C17: =COUNTIF('Test Cases'!$E$2:$E$49,B17) | D17: =SUMIFS('Test Cases'!$J$2:$J$49,'Test Cases'!$E$2:$E$49,$B17) | E17: =SUMIFS('Test Cases'!$K$2:$K$49,'Test Cases'!$E$2:$E$49,$B17) | F17: =SUMIFS('Test Cases'!$L$2:$L$49,'Test Cases'!$E$2:$E$49,$B17) | G17: =SUMIFS('Test Cases'!$M$2:$M$49,'Test Cases'!$E$2:$E$49,$B17) | H17: =IF(D17=0,"-",E17/D17)
B19: 3. Defects
B20: Severity | C20: Reported | D20: Still open
B21: Critical | C21: =COUNTIF('Defect Log'!$H$2:$H$500,B21) | D21: =COUNTIFS('Defect Log'!$H$2:$H$500,B21,'Defect Log'!$I$2:$I$500,"<>Closed",'Defect Log'!$I$2:$I$500,"<>Won't fix")
B22: Major | C22: =COUNTIF('Defect Log'!$H$2:$H$500,B22) | D22: =COUNTIFS('Defect Log'!$H$2:$H$500,B22,'Defect Log'!$I$2:$I$500,"<>Closed",'Defect Log'!$I$2:$I$500,"<>Won't fix")
B23: Minor | C23: =COUNTIF('Defect Log'!$H$2:$H$500,B23) | D23: =COUNTIFS('Defect Log'!$H$2:$H$500,B23,'Defect Log'!$I$2:$I$500,"<>Closed",'Defect Log'!$I$2:$I$500,"<>Won't fix")
B24: Cosmetic | C24: =COUNTIF('Defect Log'!$H$2:$H$500,B24) | D24: =COUNTIFS('Defect Log'!$H$2:$H$500,B24,'Defect Log'!$I$2:$I$500,"<>Closed",'Defect Log'!$I$2:$I$500,"<>Won't fix")
B25: 'Still open' counts every defect that is not Closed or Won't fix. Rows with no severity are not counted.
B27: 4. Survey
B28: Measure | C28: Value
B29: Respondents | C29: =COUNTA(Survey!$B$2:$B$500)
B30: Average SUS score (0 to 100) | C30: =IFERROR(AVERAGE(Survey!$U$2:$U$500),"No data")
B31: SUS rating | C31: =IF(ISNUMBER(C30),IF(C30>=80.3,"Excellent",IF(C30>=68,"Good",IF(C30>=51,"Below average","Poor"))),"No data")
B32: Would recommend (Yes) | C32: =IF(C29=0,"No data",COUNTIF(Survey!$S$2:$S$500,"Yes")/C29)
B33: SUS bands: 80.3+ Excellent, 68+ Good (average or better), 51+ Below average, under 51 Poor (Sauro & Lewis).
B35: Average score per UAT statement (1 to 5)
B36: Statement | C36: Average
B37: UAT 1: The system does what I expected it to do for my role. | C37: =IFERROR(AVERAGE(Survey!$N$2:$N$500),"No data")
B38: UAT 2: The messages and hints (errors, confirmations) were clear and helpful. | C38: =IFERROR(AVERAGE(Survey!$O$2:$O$500),"No data")
B39: UAT 3: I trust this system with my personal information. | C39: =IFERROR(AVERAGE(Survey!$P$2:$P$500),"No data")
B41: 5. Acceptance criteria
B42: Criterion | C42: Target | D42: Actual | E42: Status
B43: Overall pass rate | C43: 0.85 | D43: =H11 | E43: =IF(NOT(ISNUMBER(D43)),"No data yet",IF(D43>=C43,"MET","NOT MET"))
B44: High-priority pass rate | C44: 0.9 | D44: =H15 | E44: =IF(NOT(ISNUMBER(D44)),"No data yet",IF(D44>=C44,"MET","NOT MET"))
B45: Open Critical defects | C45: 0 | D45: =D21 | E45: =IF(NOT(ISNUMBER(D45)),"No data yet",IF(D45<=C45,"MET","NOT MET"))
B46: Open Major defects | C46: 2 | D46: =D22 | E46: =IF(NOT(ISNUMBER(D46)),"No data yet",IF(D46<=C46,"MET","NOT MET"))
B47: Average SUS score | C47: 68 | D47: =C30 | E47: =IF(NOT(ISNUMBER(D47)),"No data yet",IF(D47>=C47,"MET","NOT MET"))
...

Sheet Testers
B2: Tester allocation
B3: Suggested split for 50+ testers. Edit the yellow numbers; the total follows.
B5: Role | C5: Testers | D5: Test cases to run | E5: Time per tester (min)
B6: Club Committee | C6: 36 | D6: GEN core (4) + GEN-01, GEN-10 + CLB-01 to CLB-15 | E6: 45 to 60
B7: HEPA Officer | C7: 10 | D7: GEN core (4) + HEP-01 to HEP-12 | E7: 45 to 55
B8: Admin | C8: 4 | D8: GEN core (4) + ADM-01 to ADM-11 | E8: 40 to 50
B9: Total | C9: =SUM(C6:C8) | D9: Every tester also answers the 18-question survey (about 5 minutes).

Sheet Test Cases
A1: TC ID | B1: Role | C1: Module | D1: Scenario | E1: Priority | F1: All testers? | G1: Preconditions | H1: Steps | I1: Expected result | J1: Executed | K1: Pass | L1: Fail | M1: Blocked | N1: Pass rate
A2: GEN-01 | B2: General | C2: Authentication | D2: Register a new account with email verification | E2: High | F2: No | G2: Club Committee testers only (HEPA and Admin testers get an account from the facilitator). A real email address you can open. Use dummy IDs, never your real IC number. | H2: 1. Open the SEMS address and click Register. 2. Fill in every field. The role is Club Committee. Use a dummy ID such as AM2026000123. 3. Tick the Terms box and click Register. 4. Open the email and copy the 6-digit code. 5. Type the code on the verification screen. | I2: The code email arrives within about a minute. After the correct code the account is created and you land on your role's dashboard. | J2: =COUNTIFS(Results!$D$2:$D$2000,$A2,Results!$E$2:$E$2000,"Pass")+COUNTIFS(Results!$D$2:$D$2000,$A2,Results!$E$2:$E$2000,"Fail")+COUNTIFS(Results!$D$2:$D$2000,$A2,Results!$E$2:$E$2000,"Blocked") | K2: =COUNTIFS(Results!$D$2:$D$2000,$A2,Results!$E$2:$E$2000,"Pass") | L2: =COUNTIFS(Results!$D$2:$D$2000,$A2,Results!$E$2:$E$2000,"Fail") | M2: =COUNTIFS(Results!$D$2:$D$2000,$A2,Results!$E$2:$E$2000,"Blocked") | N2: =IF(J2=0,"-",K2/J2)
A3: GEN-02 | B3: General | C3: Authentication | D3: Registration form validation | E3: High | F3: Yes | G3: None. | H3: 1. Open Register and click Register with everything empty. 2. Enter an invalid email (for example abc@), a password under 8 characters and a different confirmation password. 3. Leave the Terms box unticked. | I3: Each problem is shown next to its own field in plain language. No account is created and you cannot continue until everything is fixed. | J3: =COUNTIFS(Results!$D$2:$D$2000,$A3,Results!$E$2:$E$2000,"Pass")+COUNTIFS(Results!$D$2:$D$2000,$A3,Results!$E$2:$E$2000,"Fail")+COUNTIFS(Results!$D$2:$D$2000,$A3,Results!$E$2:$E$2000,"Blocked") | K3: =COUNTIFS(Results!$D$2:$D$2000,$A3,Results!$E$2:$E$2000,"Pass") | L3: =COUNTIFS(Results!$D$2:$D$2000,$A3,Results!$E$2:$E$2000,"Fail") | M3: =COUNTIFS(Results!$D$2:$D$2000,$A3,Results!$E$2:$E$2000,"Blocked") | N3: =IF(J3=0,"-",K3/J3)
A4: GEN-03 | B4: General | C4: Authentication | D4: Sign in, sign out and a wrong password | E4: High | F4: Yes | G4: An account you registered. Do NOT try a wrong password more than twice: five wrong attempts lock the account for 15 minutes. | H4: 1. Sign in with your email and password, then log out. 2. Sign in again using your username instead of the email, then log out. 3. Try one deliberately wrong password. | I4: Email and username both work. A wrong password shows a clear error that does not reveal whether the account exists. Remember me keeps you signed in only when ticked. | J4: =COUNTIFS(Results!$D$2:$D$2000,$A4,Results!$E$2:$E$2000,"Pass")+COUNTIFS(Results!$D$2:$D$2000,$A4,Results!$E$2:$E$2000,"Fail")+COUNTIFS(Results!$D$2:$D$2000,$A4,Results!$E$2:$E$2000,"Blocked") | K4: =COUNTIFS(Results!$D$2:$D$2000,$A4,Results!$E$2:$E$2000,"Pass") | L4: =COUNTIFS(Results!$D$2:$D$2000,$A4,Results!$E$2:$E$2000,"Fail") | M4: =COUNTIFS(Results!$D$2:$D$2000,$A4,Results!$E$2:$E$2000,"Blocked") | N4: =IF(J4=0,"-",K4/J4)
A5: GEN-04 | B5: General | C5: Authentication | D5: Forgot password | E5: Medium | F5: No | G5: An account you registered. | H5: 1. On the login page click Forgot password?. 2. Enter your email, then the 6-digit code you receive. 3. Choose a new password (8+ characters) and sign in with it. | I5: Three clear steps. The code works for 10 minutes. The new password works and the old one no longer does. | J5: =COUNTIFS(Results!$D$2:$D$2000,$A5,Results!$E$2:$E$2000,"Pass")+COUNTIFS(Results!$D$2:$D$2000,$A5,Results!$E$2:$E$2000,"Fail")+COUNTIFS(Results!$D$2:$D$2000,$A5,Results!$E$2:$E$2000,"Blocked") | K5: =COUNTIFS(Results!$D$2:$D$2000,$A5,Results!$E$2:$E$2000,"Pass") | L5: =COUNTIFS(Results!$D$2:$D$2000,$A5,Results!$E$2:$E$2000,"Fail") | M5: =COUNTIFS(Results!$D$2:$D$2000,$A5,Results!$E$2:$E$2000,"Blocked") | N5: =IF(J5=0,"-",K5/J5)
A6: GEN-05 | B6: General | C6: Authentication | D6: Wrong code and resend | E6: Medium | F6: No | G6: None. | H6: 1. Start Forgot password and reach the code screen. 2. Type a wrong code and submit. 3. Click Resend code (wait for the 60-second timer first). | I6: The screen says the code is wrong and how many attempts are left (5 maximum). A resent code works and the earlier code stops working. | J6: =COUNTIFS(Results!$D$2:$D$2000,$A6,Results!$E$2:$E$2000,"Pass")+COUNTIFS(Results!$D$2:$D$2000,$A6,Results!$E$2:$E$2000,"Fail")+COUNTIFS(Results!$D$2:$D$2000,$A6,Results!$E$2:$E$2000,"Blocked") | K6: =COUNTIFS(Results!$D$2:$D$2000,$A6,Results!$E$2:$E$2000,"Pass") | L6: =COUNTIFS(Results!$D$2:$D$2000,$A6,Results!$E$2:$E$2000,"Fail") | M6: =COUNTIFS(Results!$D$2:$D$2000,$A6,Results!$E$2:$E$2000,"Blocked") | N6: =IF(J6=0,"-",K6/J6)
A7: GEN-06 | B7: General | C7: Usability | D7: Dark mode and phone layout | E7: Medium | F7: Yes | G7: A phone, or a narrow browser window. | H7: 1. Click the sun/moon icon in the top bar. 2. Open the site on your phone (or shrink the window). 3. Visit your role's main pages. | I7: The theme switches and is remembered. There is no sideways scrolling, the menu opens from the three-line icon, and all text is readable. | J7: =COUNTIFS(Results!$D$2:$D$2000,$A7,Results!$E$2:$E$2000,"Pass")+COUNTIFS(Results!$D$2:$D$2000,$A7,Results!$E$2:$E$2000,"Fail")+COUNTIFS(Results!$D$2:$D$2000,$A7,Results!$E$2:$E$2000,"Blocked") | K7: =COUNTIFS(Results!$D$2:$D$2000,$A7,Results!$E$2:$E$2000,"Pass") | L7: =COUNTIFS(Results!$D$2:$D$2000,$A7,Results!$E$2:$E$2000,"Fail") | M7: =COUNTIFS(Results!$D$2:$D$2000,$A7,Results!$E$2:$E$2000,"Blocked") | N7: =IF(J7=0,"-",K7/J7)
A8: GEN-07 | B8: General | C8: Security | D8: Pages other roles should not see | E8: High | F8: Yes | G8: Signed in with your assigned role. | H8: 1. While signed in, type the address of another role's page (for example a club member opens /admin or /hepa/review). 2. Log out, then press the browser Back button. | I8: You are sent away from pages that are not yours and no data from them is shown. After logging out, protected pages ask you to sign in. | J8: =COUNTIFS(Results!$D$2:$D$2000,$A8,Results!$E$2:$E$2000,"Pass")+COUNTIFS(Results!$D$2:$D$2000,$A8,Results!$E$2:$E$2000,"Fail")+COUNTIFS(Results!$D$2:$D$2000,$A8,Results!$E$2:$E$2000,"Blocked") | K8: =COUNTIFS(Results!$D$2:$D$2000,$A8,Results!$E$2:$E$2000,"Pass") | L8: =COUNTIFS(Results!$D$2:$D$2000,$A8,Results!$E$2:$E$2000,"Fail") | M8: =COUNTIFS(Results!$D$2:$D$2000,$A8,Results!$E$2:$E$2000,"Blocked") | N8: =IF(J8=0,"-",K8/J8)
A9: GEN-08 | B9: General | C9: Profile | D9: Profile photo and change email | E9: Medium | F9: No | G9: Signed in. | H9: 1. Open Profile, click the camera icon and upload a JPG or PNG. 2. Open Change email, enter a new address and verify it with the code. | I9: The photo appears in the top bar. The email changes only after the correct code; a wrong code is refused. | J9: =COUNTIFS(Results!$D$2:$D$2000,$A9,Results!$E$2:$E$2000,"Pass")+COUNTIFS(Results!$D$2:$D$2000,$A9,Results!$E$2:$E$2000,"Fail")+COUNTIFS(Results!$D$2:$D$2000,$A9,Results!$E$2:$E$2000,"Blocked") | K9: =COUNTIFS(Results!$D$2:$D$2000,$A9,Results!$E$2:$E$2000,"Pass") | L9: =COUNTIFS(Results!$D$2:$D$2000,$A9,Results!$E$2:$E$2000,"Fail") | M9: =COUNTIFS(Results!$D$2:$D$2000,$A9,Results!$E$2:$E$2000,"Blocked") | N9: =IF(J9=0,"-",K9/J9)
A10: GEN-09 | B10: General | C10: Profile | D10: Change password | E10: Medium | F10: No | G10: Signed in with an account whose password you know. Use a throw-away password. | H10: 1. Open Profile and find Change password. 2. Click Change password with the boxes empty, then type a wrong current password, then a new password that is too short or does not match its confirmation. 3. Enter the correct current password and a valid new password twice, then click Change password. 4. Sign out and sign in again with the new password. | I10: Each mistake is explained next to its box (wrong current password, fewer than 8 characters, passwords not matching, new password same as current). After a correct change a notice appears and you stay signed in. The new password works and the old one does not. | J10: =COUNTIFS(Results!$D$2:$D$2000,$A10,Results!$E$2:$E$2000,"Pass")+COUNTIFS(Results!$D$2:$D$2000,$A10,Results!$E$2:$E$2000,"Fail")+COUNTIFS(Results!$D$2:$D$2000,$A10,Results!$E$2:$E$2000,"Blocked") | K10: =COUNTIFS(Results!$D$2:$D$2000,$A10,Results!$E$2:$E$2000,"Pass") | L10: =COUNTIFS(Results!$D$2:$D$2000,$A10,Results!$E$2:$E$2000,"Fail") | M10: =COUNTIFS(Results!$D$2:$D$2000,$A10,Results!$E$2:$E$2000,"Blocked") | N10: =IF(J10=0,"-",K10/J10)
A11: GEN-10 | B11: General | C11: Security | D11: Only club committees can register | E11: High | F11: No | G11: Signed out. | H11: 1. Open Register and look at the Role choices. 2. Read the note under Role. | I11: Only Club Committee is offered, with a note that HEPA officer accounts are created by the administrator. There is no way to register as HEPA Officer or Admin. | J11: =COUNTIFS(Results!$D$2:$D$2000,$A11,Results!$E$2:$E$2000,"Pass")+COUNTIFS(Results!$D$2:$D$2000,$A11,Results!$E$2:$E$2000,"Fail")+COUNTIFS(Results!$D$2:$D$2000,$A11,Results!$E$2:$E$2000,"Blocked") | K11: =COUNTIFS(Results!$D$2:$D$2000,$A11,Results!$E$2:$E$2000,"Pass") | L11: =COUNTIFS(Results!$D$2:$D$2000,$A11,Results!$E$2:$E$2000,"Fail") | M11: =COUNTIFS(Results!$D$2:$D$2000,$A11,Results!$E$2:$E$2000,"Blocked") | N11: =IF(J11=0,"-",K11/J11)
A12: CLB-01 | B12: Club Committee | C12: Dashboard | D12: Dashboard and statistics | E12: High | F12: No | G12: Signed in as a club committee member. | H12: 1. Open the dashboard. 2. Click a statistic card such as Draft. | I12: Five statistics (Draft, Under Review, Requires Changes, Approved, Rejected) match My Proposals. Clicking a card filters the table. The Create Proposal button is easy to find. | J12: =COUNTIFS(Results!$D$2:$D$2000,$A12,Results!$E$2:$E$2000,"Pass")+COUNTIFS(Results!$D$2:$D$2000,$A12,Results!$E$2:$E$2000,"Fail")+COUNTIFS(Results!$D$2:$D$2000,$A12,Results!$E$2:$E$2000,"Blocked") | K12: =COUNTIFS(Results!$D$2:$D$2000,$A12,Results!$E$2:$E$2000,"Pass") | L12: =COUNTIFS(Results!$D$2:$D$2000,$A12,Results!$E$2:$E$2000,"Fail") | M12: =COUNTIFS(Results!$D$2:$D$2000,$A12,Results!$E$2:$E$2000,"Blocked") | N12: =IF(J12=0,"-",K12/J12)
A13: CLB-02 | B13: Club Committee | C13: Create proposal | D13: Step validation | E13: High | F13: No | G13: None. | H13: 1. Click Create Proposal. 2. Click Next without typing anything. | I13: Required fields are flagged with helpful messages, the first problem gets focus, and you cannot move on. | J13: =COUNTIFS(Results!$D$2:$D$2000,$A13,Results!$E$2:$E$2000,"Pass")+COUNTIFS(Results!$D$2:$D$2000,$A13,Results!$E$2:$E$2000,"Fail")+COUNTIFS(Results!$D$2:$D$2000,$A13,Results!$E$2:$E$2000,"Blocked") | K13: =COUNTIFS(Results!$D$2:$D$2000,$A13,Results!$E$2:$E$2000,"Pass") | L13: =COUNTIFS(Results!$D$2:$D$2000,$A13,Results!$E$2:$E$2000,"Fail") | M13: =COUNTIFS(Results!$D$2:$D$2000,$A13,Results!$E$2:$E$2000,"Blocked") | N13: =IF(J13=0,"-",K13/J13)
... A49: ADM-11 | B49: Admin | C49: Settings | D49: Upload rules are enforced | E49: Medium | F49: No | G49: A club account to test uploading. | H49: 1. Open Settings and lower the maximum upload size or remove an allowed file type, then save. 2. As a club member, try to upload a file that now breaks the rule. | I49: The upload is refused with a clear message. Restoring the setting allows it again. | J49: =COUNTIFS(Results!$D$2:$D$2000,$A49,Results!$E$2:$E$2000,"Pass")+COUNTIFS(Results!$D$2:$D$2000,$A49,Results!$E$2:$E$2000,"Fail")+COUNTIFS(Results!$D$2:$D$2000,$A49,Results!$E$2:$E$2000,"Blocked") | K49: =COUNTIFS(Results!$D$2:$D$2000,$A49,Results!$E$2:$E$2000,"Pass") | L49: =COUNTIFS(Results!$D$2:$D$2000,$A49,Results!$E$2:$E$2000,"Fail") | M49: =COUNTIFS(Results!$D$2:$D$2000,$A49,Results!$E$2:$E$2000,"Blocked") | N49: =IF(J49=0,"-",K49/J49)

Sheet Results
A1: Tester ID | B1: Tester name | C1: Role | D1: TC ID | E1: Result | F1: Comment | G1: Date tested | H1: Defect ID

Sheet Defect Log
A1: Defect ID | B1: Date reported | C1: Reported by (Tester ID) | D1: Related TC ID | E1: Role | F1: Summary | G1: Steps to reproduce | H1: Severity | I1: Status | J1: Screenshot / link | K1: Fix notes | L1: Date closed

Sheet Survey
A1: Timestamp | B1: Tester ID | C1: Device | D1: SUS 1 | E1: SUS 2 | F1: SUS 3 | G1: SUS 4 | H1: SUS 5 | I1: SUS 6 | J1: SUS 7 | K1: SUS 8 | L1: SUS 9 | M1: SUS 10 | N1: UAT 1 | O1: UAT 2 | P1: UAT 3 | Q1: Most confusing / errors seen | R1: One change | S1: Recommend | T1: Role (optional) | U1: SUS score
U2: =IF(COUNT(D2:M2)=10,((D2-1)+(5-E2)+(F2-1)+(5-G2)+(H2-1)+(5-I2)+(J2-1)+(5-K2)+(L2-1)+(5-M2))*2.5,"")
U3: =IF(COUNT(D3:M3)=10,((D3-1)+(5-E3)+(F3-1)+(5-G3)+(H3-1)+(5-I3)+(J3-1)+(5-K3)+(L3-1)+(5-M3))*2.5,"")
U4: =IF(COUNT(D4:M4)=10,((D4-1)+(5-E4)+(F4-1)+(5-G4)+(H4-1)+(5-I4)+(J4-1)+(5-K4)+(L4-1)+(5-M4))*2.5,"")
U5: =IF(COUNT(D5:M5)=10,((D5-1)+(5-E5)+(F5-1)+(5-G5)+(H5-1)+(5-I5)+(J5-1)+(5-K5)+(L5-1)+(5-M5))*2.5,"")
U6: =IF(COUNT(D6:M6)=10,((D6-1)+(5-E6)+(F6-1)+(5-G6)+(H6-1)+(5-I6)+(J6-1)+(5-K6)+(L6-1)+(5-M6))*2.5,"")
U7: =IF(COUNT(D7:M7)=10,((D7-1)+(5-E7)+(F7-1)+(5-G7)+(H7-1)+(5-I7)+(J7-1)+(5-K7)+(L7-1)+(5-M7))*2.5,"")
U8: =IF(COUNT(D8:M8)=10,((D8-1)+(5-E8)+(F8-1)+(5-G8)+(H8-1)+(5-I8)+(J8-1)+(5-K8)+(L8-1)+(5-M8))*2.5,"")
U9: =IF(COUNT(D9:M9)=10,((D9-1)+(5-E9)+(F9-1)+(5-G9)+(H9-1)+(5-I9)+(J9-1)+(5-K9)+(L9-1)+(5-M9))*2.5,"")
U10: =IF(COUNT(D10:M10)=10,((D10-1)+(5-E10)+(F10-1)+(5-G10)+(H10-1)+(5-I10)+(J10-1)+(5-K10)+(L10-1)+(5-M10))*2.5,"")
U11: =IF(COUNT(D11:M11)=10,((D11-1)+(5-E11)+(F11-1)+(5-G11)+(H11-1)+(5-I11)+(J11-1)+(5-K11)+(L11-1)+(5-M11))*2.5,"")
U12: =IF(COUNT(D12:M12)=10,((D12-1)+(5-E12)+(F12-1)+(5-G12)+(H12-1)+(5-I12)+(J12-1)+(5-K12)+(L12-1)+(5-M12))*2.5,"")
U13: =IF(COUNT(D13:M13)=10,((D13-1)+(5-E13)+(F13-1)+(5-G13)+(H13-1)+(5-I13)+(J13-1)+(5-K13)+(L13-1)+(5-M13))*2.5,"")
... U500: =IF(COUNT(D500:M500)=10,((D500-1)+(5-E500)+(F500-1)+(5-G500)+(H500-1)+(5-I500)+(J500-1)+(5-K500)+(L500-1)+(5-M500))*2.5,"")
A503: Paste the Google Form response rows into columns A to S. The SUS score in column U is calculated. Scale: 1 = strongly disagree ... 5 = strongly agree; SUS items 2, 4, 6, 8 and 10 are negatively worded and the formula already reverses them.
